Workbook

Sheet Brain tumor Desk Research
G1: India Brain tumor Market
C2: Project Details
A3: 148 | C3: Indication | D3: Brain tumor
A4: =A3*10^6 -> 148000000 | C4: Geography | D4: India | H4: Input | I4: 2023 | J4: =I4+1 -> 2024 | K4: =J4+1 -> 2025 | L4: =K4+1 -> 2026 | M4: =L4+1 -> 2027 | N4: =M4+1 -> 2028 | O4: =N4+1 -> 2029 | P4: =O4+1 -> 2030 | Q4: =P4+1 -> 2031 | ... T4: =S4+1 -> 2034 | U4: CAGR(2027-2034) | W4: 2024 | X4: =W4+1 -> 2025 | Y4: =X4+1 -> 2026 | Z4: =Y4+1 -> 2027 | AA4: =Z4+1 -> 2028 | AB4: =AA4+1 -> 2029 | AC4: =AB4+1 -> 2030 | AD4: =AC4+1 -> 2031 | AE4: =AD4+1 -> 2032 | ... AG4: =AF4+1 -> 2034
C5: Total Market Size | G5: Population | H5: 143 Million | I5: 143000000 | L5: 148000000 | W5: 0.014946601 | X5: 0.015360904 | Y5: 0.015786691 | Z5: 0.016224281 | AA5: 0.016674 | AB5: 0.017136185 | AC5: 0.017611181 | AD5: 0.018099344 | AE5: 0.018601038 | AF5: 0.019116638 | AG5: 0.01964653
G6: Adults (30–60 years) | H6: 0.32 | I6: 45760000 | J6: =I6*(1+W5) -> 46443956 | K6: =$J6*(1+X5) -> 47157378 | L6: =$J6*(1+Y5) -> 47177153 | M6: =$J6*(1+Z5) -> 47197476 | N6: =$J6*(1+AA5) -> 47218363 | O6: =$J6*(1+AB5) -> 47239829 | P6: =$J6*(1+AC5) -> 47261889 | Q6: =$J6*(1+AD5) -> 47284562 | R6: =$J6*(1+AE5) -> 47307862 | ... T6: =$J6*(1+AG5) -> 47356419 | W6: 0.023 | X6: 0.023192579 | Y6: 0.023386771 | Z6: 0.023582589 | AA6: 0.023780047 | AB6: 0.023979158 | AC6: 0.024179936 | AD6: 0.024382395 | AE6: 0.024586549 | AF6: 0.024792413 | AG6: 0.025
G7: Pediatric (0–19 years) | H7: 0.3129 | I7: 44744700 | J7: =I7*(1+W6) -> 45773828 | K7: =J7*(1+X6) -> 46835441 | L7: =K7*(1+Y6) -> 47930771 | M7: =L7*(1+Z6) -> 49061103 | N7: =M7*(1+AA6) -> 50227778 | O7: =N7*(1+AB6) -> 51432198 | P7: =O7*(1+AC6) -> 52675825 | Q7: =P7*(1+AD6) -> 53960188 | ... T7: =S7*(1+AG6) -> 58074017 | W7: 0.02 | X7: 0.020367988 | Y7: 0.020742746 | Z7: 0.021124399 | AA7: 0.021513075 | AB7: 0.021908902 | AC7: 0.022312012 | AD7: 0.02272254 | AE7: 0.02314062 | AF7: 0.023566393 | AG7: 0.024
G8: Older Adults (60+ years) | H8: 0.106 | I8: 15158000 | J8: =I8*(1+W7) -> 15461160 | K8: =J8*(1+X7) -> 15776073 | L8: =K8*(1+Y7) -> 16103312 | M8: =L8*(1+Z7) -> 16443485 | N8: =M8*(1+AA7) -> 16797234 | O8: =N8*(1+AB7) -> 17165243 | P8: =O8*(1+AC7) -> 17548235 | Q8: =P8*(1+AD7) -> 17946975 | ... T8: =S8*(1+AG7) -> 19246092
C9: Forecast Year | D9: 2023-2034 | G9: Prevelance Rate % | H9: 0.02 | I9: 0.02 | J9: 0.020255734 | K9: 0.020514738 | L9: 0.020777053 | M9: 0.021042723 | N9: 0.02131179 | O9: 0.021584297 | P9: 0.021860289 | Q9: 0.022139809 | R9: 0.022422904 | S9: 0.022709619 | T9: 0.023
G10: Prevelance Pool | I10: =I6*I9 -> 915200 | J10: =J9*J6 -> 940756.42 | K10: =K9*K6 -> 967421.23 | L10: =L9*L6 -> 980202.22 | M10: =M9*M6 -> 993163.42 | N10: =N9*N6 -> 1006307.8 | O10: =O9*O6 -> 1019638.5 | P10: =P9*P6 -> 1033158.5 | Q10: =Q9*Q6 -> 1046871.2 | ... T10: =T9*T6 -> 1089197.6
C11: India Population | D11: 1.47 billion in 2026 | G11: Presentation Rate % | H11: 0.85 | I11: 0.85791511 | J11: 0.86590392 | K11: 0.87396712 | L11: 0.88210541 | M11: 0.89031948 | N11: 0.89861004 | O11: 0.9069778 | P11: 0.91542348 | Q11: 0.9239478 | R11: 0.9325515 | S11: 0.94123532 | T11: 0.95
D12: 1.43 Billion | G12: Prevelance Pool with Presentation | I12: =I11*I10 -> 785163.91 | J12: =J11*J10 -> 814604.67 | K12: =K11*K10 -> 845494.35 | L12: =L11*L10 -> 864641.68 | M12: =M11*M10 -> 884232.74 | N12: =N11*N10 -> 904278.31 | O12: =O11*O10 -> 924789.47 | P12: =P11*P10 -> 945777.59 | ... T12: =T11*T10 -> 1034737.8
D13: 143,000 Million in 2023 | G13: Dignosis Rate % | H13: 0.7 | I13: 0.7 | J13: 0.71246507 | K13: 0.7251521 | L13: 0.73806506 | M13: 0.75120796 | N13: 0.7645849 | O13: 0.77820004 | P13: 0.79205764 | Q13: 0.806162 | R13: 0.82051751 | S13: 0.83512866 | T13: 0.85
D14: 143 | G14: Dignosed Prevelance Pool | I14: =I13*I12 -> 549614.73 | J14: =J13*J12 -> 580377.37 | K14: =K13*K12 -> 613112 | L14: =L13*L12 -> 638161.81 | M14: =M13*M12 -> 664242.67 | N14: =N13*N12 -> 691397.54 | O14: =O13*O12 -> 719671.21 | P14: =P13*P12 -> 749110.36 | ... T14: =T13*T12 -> 879527.09
G15: Grade 1 brain cancer | H15: 0.24 | I15: =$H15*I14 -> 131907.54 | J15: =$H15*J14 -> 139290.57 | K15: =$H15*K14 -> 147146.88 | L15: =$H15*L14 -> 153158.83 | M15: =$H15*M14 -> 159418.24 | N15: =$H15*N14 -> 165935.41 | O15: =$H15*O14 -> 172721.09 | P15: =$H15*P14 -> 179786.49 | ... T15: =$H15*T14 -> 211086.5
G16: Grade 2 brain cancer | H16: 0.162 | I16: =$H16*I14 -> 89037.587 | J16: =$H16*J14 -> 94021.134 | K16: =$H16*K14 -> 99324.145 | L16: =$H16*L14 -> 103382.21 | M16: =$H16*M14 -> 107607.31 | N16: =$H16*N14 -> 112006.4 | O16: =$H16*O14 -> 116586.74 | P16: =$H16*P14 -> 121355.88 | ... T16: =$H16*T14 -> 142483.39
G17: Grade 3 brain cancer | H17: 0.39 | I17: =$H17*I14 -> 214349.75 | J17: =$H17*J14 -> 226347.17 | K17: =$H17*K14 -> 239113.68 | L17: =$H17*L14 -> 248883.11 | M17: =$H17*M14 -> 259054.64 | N17: =$H17*N14 -> 269645.04 | O17: =$H17*O14 -> 280671.77 | P17: =$H17*P14 -> 292153.04 | ... T17: =$H17*T14 -> 343015.57
G18: Grade 4 brain cancer | H18: =1-SUM(H15:H17) -> 0.208 | I18: =$H18*I14 -> 114319.86 | J18: =$H18*J14 -> 120718.49 | K18: =$H18*K14 -> 127527.3 | L18: =$H18*L14 -> 132737.66 | M18: =$H18*M14 -> 138162.48 | N18: =$H18*N14 -> 143810.69 | O18: =$H18*O14 -> 149691.61 | P18: =$H18*P14 -> 155814.96 | ... T18: =$H18*T14 -> 182941.64
C19: 2023 | D19: =D14*10^6 -> 143000000 | E19: =D19*F22 -> 15158000 | G19: Treatment Prevelant Pool | I19: =(I15*30%)+(I16*45%)+(I17*60%)+(I18*92%) -> 313423.3 | J19: =(J15*30%)+(J16*45%)+(J17*60%)+(J18*92%) -> 330966 | K19: =(K15*30%)+(K16*45%)+(K17*60%)+(K18*92%) -> 349633.25 | L19: =(L15*30%)+(L16*45%)+(L17*60%)+(L18*92%) -> 363918.15 | M19: =(M15*30%)+(M16*45%)+(M17*60%)+(M18*92%) -> 378791.02 | N19: =(N15*30%)+(N16*45%)+(N17*60%)+(N18*92%) -> 394276.36 | O19: =(O15*30%)+(O16*45%)+(O17*60%)+(O18*92%) -> 410399.7 | P19: =(P15*30%)+(P16*45%)+(P17*60%)+(P18*92%) -> 427187.67 | ... T19: =(T15*30%)+(T16*45%)+(T17*60%)+(T18*92%) -> 501559.12
C20: Brain Cases By agae | D20: Adults (30–60 years) | E20: 460 | F20: 0.32 | G20: Accces Rate % | H20: 0.85 | I20: 0.85 | J20: 0.85613721 | K20: 0.86231873 | L20: 0.86854488 | M20: 0.87481598 | N20: 0.88113237 | O20: 0.88749435 | P20: 0.89390228 | Q20: 0.90035647 | R20: 0.90685726 | S20: 0.91340499 | T20: 0.92
D21: Pediatric (0–19 years) | E21: 450 | F21: 0.3129 | G21: Acesses Rated Pool | I21: =I20*I19 -> 266409.8 | J21: =J20*J19 -> 283352.31 | K21: =K20*K19 -> 301495.3 | L21: =L20*L19 -> 316079.25 | M21: =M20*M19 -> 331372.44 | N21: =N20*N19 -> 347409.66 | O21: =O20*O19 -> 364227.42 | P21: =P20*P19 -> 381864.04 | ... T21: =T20*T19 -> 461434.39
D22: Older Adults (60+ years) | E22: 153 | F22: 0.106 | G22: Treatment Rate % | I22: 0.899 | J22: 0.89909086 | K22: 0.89918174 | L22: 0.89927262 | M22: 0.89936351 | N22: 0.89945441 | O22: 0.89954532 | P22: 0.89963624 | Q22: 0.89972716 | R22: 0.8998181 | S22: 0.89990904 | T22: 0.9
G23: Treatable Pool | I23: =I22*I21 -> 239502.41 | J23: =J22*J21 -> 254759.47 | K23: =K22*K21 -> 271099.07 | L23: =L22*L21 -> 284241.41 | M23: =M22*M21 -> 298024.28 | N23: =N22*N21 -> 312479.15 | O23: =O22*O21 -> 327639.07 | P23: =P22*P21 -> 343538.72 | ... T23: =T22*T21 -> 415290.95
G25: Market Drugs
G26: Chemotherapy
G27: Temozolomide (Temodar) | I27: 0.02 | J27: 0.021189262 | K27: 0.022449241 | L27: 0.023784142 | M27: 0.025198421 | N27: 0.026696797 | O27: 0.028284271 | P27: 0.029966142 | Q27: 0.031748021 | R27: 0.033635857 | S27: 0.035635949 | T27: 0.037754973
G28: Nitrosoureas (Lomustine (CCNU) and Carmustine (BCNU) | I28: 0.1 | J28: 0.10117149 | K28: 0.10235671 | L28: 0.10355581 | M28: 0.10476896 | N28: 0.10599631 | O28: 0.10723805 | P28: 0.10849434 | Q28: 0.10976534 | R28: 0.11105123 | S28: 0.11235219 | T28: 0.11366838
G29: PCV Regimen (Procarbazine, CCNU,Vincristine) | I29: 0.03 | J29: 0.030727895 | K29: 0.031473452 | L29: 0.032237098 | M29: 0.033019272 | N29: 0.033820425 | O29: 0.034641016 | P29: 0.035481517 | Q29: 0.036342412 | R29: 0.037224194 | S29: 0.038127372 | T29: 0.039052463
G30: others | I30: 0.035 | J30: 0.03574073 | K30: 0.036497136 | L30: 0.037269551 | M30: 0.038058313 | N30: 0.038863768 | O30: 0.03968627 | P30: 0.040526178 | Q30: 0.041383863 | R30: 0.042259699 | S30: 0.043154071 | T30: 0.044067371
G31: Targeted Therapies
G32: Bevacizumab (Avastin) | I32: 0.03 | J32: 0.030727895 | K32: 0.031473452 | L32: 0.032237098 | M32: 0.033019272 | N32: 0.033820425 | O32: 0.034641016 | P32: 0.035481517 | Q32: 0.036342412 | R32: 0.037224194 | S32: 0.038127372 | T32: 0.039052463
G33: Vorasidenib (Voranigo) | I33: 0.056 | J33: 0.056322894 | K33: 0.05664765 | L33: 0.056974278 | M33: 0.05730279 | N33: 0.057633196 | O33: 0.057965507 | P33: 0.058299734 | Q33: 0.058635888 | R33: 0.058973981 | S33: 0.059314023 | T33: 0.059656025
G34: Everolimus | I34: 0.06 | J34: 0.060775725 | K34: 0.06156148 | L34: 0.062357393 | M34: 0.063163596 | N34: 0.063980222 | O34: 0.064807407 | P34: 0.065645286 | Q34: 0.066493998 | R34: 0.067353682 | S34: 0.068224481 | T34: 0.069106539
G35: others | I35: 0.065 | J35: 0.0661345 | K35: 0.067288802 | L35: 0.06846325 | M35: 0.069658198 | N35: 0.070874001 | O35: 0.072111026 | P35: 0.07336964 | Q35: 0.074650223 | R35: 0.075953157 | S35: 0.077278832 | T35: 0.078627645
G36: Supportive Medications
G37: Corticosteroids (e.g., Dexamethasone) | I37: 0.06 | J37: 0.060775725 | K37: 0.06156148 | L37: 0.062357393 | M37: 0.063163596 | N37: 0.063980222 | O37: 0.064807407 | P37: 0.065645286 | Q37: 0.066493998 | R37: 0.067353682 | S37: 0.068224481 | T37: 0.069106539
G38: Anticonvulsants (e.g., Levetiracetam) | I38: 0.075 | J38: 0.07614821 | K38: 0.077313999 | L38: 0.078497635 | M38: 0.079699393 | N38: 0.080919548 | O38: 0.082158384 | P38: 0.083416185 | Q38: 0.084693243 | R38: 0.085989851 | S38: 0.08730631 | T38: 0.088642924
G39: others | I39: 0.08 | J39: 0.081501541 | K39: 0.083031265 | L39: 0.084589701 | M39: 0.086177388 | N39: 0.087794874 | O39: 0.089442719 | P39: 0.091121493 | Q39: 0.092831777 | R39: 0.094574161 | S39: 0.096349248 | T39: 0.098157653
G41: Pipline
G42: A | N42: 0.024007125 | O42: 0.028332389 | P42: 0.033436919 | Q42: 0.039461111 | R42: 0.046570657 | S42: 0.0549611 | T42: 0.064863214
...

Sheet Drug Price
A1: Chemotherapy | B1: 2023 | C1: =B1+1 -> 2024 | D1: =C1+1 -> 2025 | E1: =D1+1 -> 2026 | F1: =E1+1 -> 2027 | G1: =F1+1 -> 2028 | H1: =G1+1 -> 2029 | I1: =H1+1 -> 2030 | J1: =I1+1 -> 2031 | ... M1: =L1+1 -> 2034
A2: Temozolomide (Temodar) | B2: 29 | C2: 31.293888 | D2: 33.769222 | E2: 36.440353 | F2: 39.322771 | G2: 42.433186 | H2: 45.789633 | I2: 49.411574 | J2: 53.32001 | K2: 57.537601 | L2: 62.088801 | M2: 67
A3: Nitrosoureas (Lomustine (CCNU) and Carmustine (BCNU) | B3: 90 | C3: 90.866182 | D3: 91.740701 | E3: 92.623636 | F3: 93.515069 | G3: 94.415081 | H3: 95.323755 | I3: 96.241174 | J3: 97.167423 | K3: 98.102586 | L3: 99.04675 | M3: 100
A4: PCV Regimen (Procarbazine, CCNU,Vincristine) | B4: 87 | C4: 87.443088 | D4: 87.888433 | E4: 88.336046 | F4: 88.785938 | G4: 89.238122 | H4: 89.692609 | I4: 90.14941 | J4: 90.608538 | K4: 91.070005 | L4: 91.533821 | M4: 92
A5: others | B5: 56 | C5: 57.147604 | D5: 58.318726 | E5: 59.513848 | F5: 60.733461 | G5: 61.978068 | H5: 63.24818 | I5: 64.544321 | J5: 65.867023 | K5: 67.216832 | L5: 68.594302 | M5: 70
A6: Targeted Therapies
A7: Bevacizumab (Avastin) | B7: 89 | C7: 89.268636 | D7: 89.538083 | E7: 89.808343 | F7: 90.079419 | G7: 90.351314 | H7: 90.624028 | I7: 90.897566 | J7: 91.17193 | K7: 91.447122 | L7: 91.723144 | M7: 92
A8: Vorasidenib (Voranigo) | B8: 27 | C8: 27.259855 | D8: 27.52221 | E8: 27.787091 | F8: 28.054521 | G8: 28.324524 | H8: 28.597126 | I8: 28.872352 | J8: 29.150227 | K8: 29.430776 | L8: 29.714025 | M8: 30
A9: Everolimus | B9: 86 | C9: 86.356169 | D9: 86.713812 | E9: 87.072937 | F9: 87.433549 | G9: 87.795655 | H9: 88.15926 | I9: 88.524371 | J9: 88.890995 | K9: 89.259136 | L9: 89.628803 | M9: 90
A10: others | B10: 90 | C10: 90.866182 | D10: 91.740701 | E10: 92.623636 | F10: 93.515069 | G10: 94.415081 | H10: 95.323755 | I10: 96.241174 | J10: 97.167423 | K10: 98.102586 | L10: 99.04675 | M10: 100
A11: Supportive Medications
A12: Corticosteroids (e.g., Dexamethasone) | B12: 67 | C12: 67.26733 | D12: 67.535726 | E12: 67.805193 | F12: 68.075736 | G12: 68.347358 | H12: 68.620063 | I12: 68.893857 | J12: 69.168743 | K12: 69.444726 | L12: 69.72181 | M12: 70
A13: Anticonvulsants (e.g., Levetiracetam) | B13: 100 | C13: 100.44453 | D13: 100.89104 | E13: 101.33953 | F13: 101.79002 | G13: 102.24251 | H13: 102.69701 | I13: 103.15353 | J13: 103.61208 | K13: 104.07267 | L13: 104.53531 | M13: 105
A14: others | B14: 56 | C14: 56.35234 | D14: 56.706897 | E14: 57.063685 | F14: 57.422718 | G14: 57.78401 | H14: 58.147574 | I14: 58.513427 | J14: 58.881581 | K14: 59.252051 | L14: 59.624853 | M14: 60
A16: Pipline
A17: A | G17: 47.20754 | H17: 47.661877 | I17: 48.120587 | J17: 48.583711 | K17: 49.051293 | L17: 49.523375 | M17: 50
A18: B | G18: 78.902816 | H18: 79.08463 | I18: 79.266862 | J18: 79.449514 | K18: 79.632587 | L18: 79.816082 | M18: 80
A19: c | G19: 24.738908 | H19: 25.102159 | I19: 25.470743 | J19: 25.844739 | K19: 26.224226 | L19: 26.609286 | M19: 27
A20: D | G20: 89.453161 | H20: 89.544069 | I20: 89.63507 | J20: 89.726164 | K20: 89.81735 | L20: 89.908628 | M20: 90
A21: others | B21: 67 | C21: 67.26733 | D21: 67.535726 | E21: 67.805193 | F21: 68.075736 | G21: 68.347358 | H21: 68.620063 | I21: 68.893857 | J21: 69.168743 | K21: 69.444726 | L21: 69.72181 | M21: 70

Sheet Description 
